[2023-10-07T00:00:10.918+0000] {taskinstance.py:1103} INFO - Dependencies all met for dep_context=non-requeueable deps ti=<TaskInstance: web_scraping_dag.run_container scheduled__2023-10-06T00:00:00+00:00 [queued]>
[2023-10-07T00:00:10.944+0000] {taskinstance.py:1103} INFO - Dependencies all met for dep_context=requeueable deps ti=<TaskInstance: web_scraping_dag.run_container scheduled__2023-10-06T00:00:00+00:00 [queued]>
[2023-10-07T00:00:10.945+0000] {taskinstance.py:1308} INFO - Starting attempt 1 of 2
[2023-10-07T00:00:10.987+0000] {taskinstance.py:1327} INFO - Executing <Task(DockerOperator): run_container> on 2023-10-06 00:00:00+00:00
[2023-10-07T00:00:11.017+0000] {standard_task_runner.py:57} INFO - Started process 18048 to run task
[2023-10-07T00:00:11.036+0000] {standard_task_runner.py:84} INFO - Running: ['***', 'tasks', 'run', 'web_scraping_dag', 'run_container', 'scheduled__2023-10-06T00:00:00+00:00', '--job-id', '619', '--raw', '--subdir', 'DAGS_FOLDER/web_scrapping_test.py', '--cfg-path', '/tmp/tmpfwe9bdke']
[2023-10-07T00:00:11.042+0000] {standard_task_runner.py:85} INFO - Job 619: Subtask run_container
[2023-10-07T00:00:11.246+0000] {task_command.py:410} INFO - Running <TaskInstance: web_scraping_dag.run_container scheduled__2023-10-06T00:00:00+00:00 [running]> on host 3c74e60f688b
[2023-10-07T00:00:11.582+0000] {taskinstance.py:1545} INFO - Exporting env vars: AIRFLOW_CTX_DAG_OWNER='***' AIRFLOW_CTX_DAG_ID='web_scraping_dag' AIRFLOW_CTX_TASK_ID='run_container' AIRFLOW_CTX_EXECUTION_DATE='2023-10-06T00:00:00+00:00' AIRFLOW_CTX_TRY_NUMBER='1' AIRFLOW_CTX_DAG_RUN_ID='scheduled__2023-10-06T00:00:00+00:00'
[2023-10-07T00:00:11.868+0000] {docker.py:327} INFO - Pulling docker image my_selenium_image
[2023-10-07T00:00:14.228+0000] {taskinstance.py:1824} ERROR - Task failed with exception
Traceback (most recent call last):
  File "/home/airflow/.local/lib/python3.10/site-packages/docker/api/client.py", line 268, in _raise_for_status
    response.raise_for_status()
  File "/home/airflow/.local/lib/python3.10/site-packages/requests/models.py", line 1021, in raise_for_status
    raise HTTPError(http_error_msg, response=self)
requests.exceptions.HTTPError: 404 Client Error: Not Found for url: http://docker-socket-proxy:2375/v1.41/images/create?tag=latest&fromImage=my_selenium_image

The above exception was the direct cause of the following exception:

Traceback (most recent call last):
  File "/home/airflow/.local/lib/python3.10/site-packages/airflow/providers/docker/operators/docker.py", line 329, in execute
    for output in self.cli.pull(self.image, stream=True, decode=True):
  File "/home/airflow/.local/lib/python3.10/site-packages/docker/api/image.py", line 429, in pull
    self._raise_for_status(response)
  File "/home/airflow/.local/lib/python3.10/site-packages/docker/api/client.py", line 270, in _raise_for_status
    raise create_api_error_from_http_exception(e) from e
  File "/home/airflow/.local/lib/python3.10/site-packages/docker/errors.py", line 39, in create_api_error_from_http_exception
    raise cls(e, response=response, explanation=explanation) from e
docker.errors.ImageNotFound: 404 Client Error for http://docker-socket-proxy:2375/v1.41/images/create?tag=latest&fromImage=my_selenium_image: Not Found ("pull access denied for my_selenium_image, repository does not exist or may require 'docker login': denied: requested access to the resource is denied")
[2023-10-07T00:00:14.274+0000] {taskinstance.py:1345} INFO - Marking task as UP_FOR_RETRY. dag_id=web_scraping_dag, task_id=run_container, execution_date=20231006T000000, start_date=20231007T000010, end_date=20231007T000014
[2023-10-07T00:00:14.337+0000] {standard_task_runner.py:104} ERROR - Failed to execute job 619 for task run_container (404 Client Error for http://docker-socket-proxy:2375/v1.41/images/create?tag=latest&fromImage=my_selenium_image: Not Found ("pull access denied for my_selenium_image, repository does not exist or may require 'docker login': denied: requested access to the resource is denied"); 18048)
[2023-10-07T00:00:14.386+0000] {local_task_job_runner.py:225} INFO - Task exited with return code 1
[2023-10-07T00:00:14.427+0000] {taskinstance.py:2653} INFO - 0 downstream tasks scheduled from follow-on schedule check
