[2023-09-27T16:32:39.662+0000] {taskinstance.py:1103} INFO - Dependencies all met for dep_context=non-requeueable deps ti=<TaskInstance: web_scraping_dag.build_image manual__2023-09-27T16:31:30.840955+00:00 [queued]>
[2023-09-27T16:32:39.679+0000] {taskinstance.py:1103} INFO - Dependencies all met for dep_context=requeueable deps ti=<TaskInstance: web_scraping_dag.build_image manual__2023-09-27T16:31:30.840955+00:00 [queued]>
[2023-09-27T16:32:39.679+0000] {taskinstance.py:1308} INFO - Starting attempt 2 of 2
[2023-09-27T16:32:39.698+0000] {taskinstance.py:1327} INFO - Executing <Task(DockerOperator): build_image> on 2023-09-27 16:31:30.840955+00:00
[2023-09-27T16:32:39.703+0000] {standard_task_runner.py:57} INFO - Started process 1847 to run task
[2023-09-27T16:32:39.707+0000] {standard_task_runner.py:84} INFO - Running: ['***', 'tasks', 'run', 'web_scraping_dag', 'build_image', 'manual__2023-09-27T16:31:30.840955+00:00', '--job-id', '275', '--raw', '--subdir', 'DAGS_FOLDER/web_scrapping_test.py', '--cfg-path', '/tmp/tmpiudx8_9m']
[2023-09-27T16:32:39.708+0000] {standard_task_runner.py:85} INFO - Job 275: Subtask build_image
[2023-09-27T16:32:39.768+0000] {task_command.py:410} INFO - Running <TaskInstance: web_scraping_dag.build_image manual__2023-09-27T16:31:30.840955+00:00 [running]> on host 99db4f9ebf5f
[2023-09-27T16:32:39.859+0000] {taskinstance.py:1547} INFO - Exporting env vars: AIRFLOW_CTX_DAG_OWNER='***' AIRFLOW_CTX_DAG_ID='web_scraping_dag' AIRFLOW_CTX_TASK_ID='build_image' AIRFLOW_CTX_EXECUTION_DATE='2023-09-27T16:31:30.840955+00:00' AIRFLOW_CTX_TRY_NUMBER='2' AIRFLOW_CTX_DAG_RUN_ID='manual__2023-09-27T16:31:30.840955+00:00'
[2023-09-27T16:32:39.943+0000] {docker.py:246} INFO - Starting docker container from image my_selenium_image
[2023-09-27T16:32:40.643+0000] {taskinstance.py:1824} ERROR - Task failed with exception
Traceback (most recent call last):
  File "/home/airflow/.local/lib/python3.7/site-packages/docker/api/client.py", line 268, in _raise_for_status
    response.raise_for_status()
  File "/home/airflow/.local/lib/python3.7/site-packages/requests/models.py", line 1021, in raise_for_status
    raise HTTPError(http_error_msg, response=self)
requests.exceptions.HTTPError: 400 Client Error: Bad Request for url: http://docker-socket-proxy:2375/v1.41/containers/524c514bf081d1ef02fb1aec345595c5d259e70cf40d2d0f7099aa2e2e91a262/start

The above exception was the direct cause of the following exception:

Traceback (most recent call last):
  File "/home/airflow/.local/lib/python3.7/site-packages/airflow/providers/docker/operators/docker.py", line 343, in execute
    return self._run_image()
  File "/home/airflow/.local/lib/python3.7/site-packages/airflow/providers/docker/operators/docker.py", line 265, in _run_image
    return self._run_image_with_mounts(self.mounts, add_tmp_variable=False)
  File "/home/airflow/.local/lib/python3.7/site-packages/airflow/providers/docker/operators/docker.py", line 297, in _run_image_with_mounts
    self.cli.start(self.container['Id'])
  File "/home/airflow/.local/lib/python3.7/site-packages/docker/utils/decorators.py", line 19, in wrapped
    return f(self, resource_id, *args, **kwargs)
  File "/home/airflow/.local/lib/python3.7/site-packages/docker/api/container.py", line 1127, in start
    self._raise_for_status(res)
  File "/home/airflow/.local/lib/python3.7/site-packages/docker/api/client.py", line 270, in _raise_for_status
    raise create_api_error_from_http_exception(e) from e
  File "/home/airflow/.local/lib/python3.7/site-packages/docker/errors.py", line 39, in create_api_error_from_http_exception
    raise cls(e, response=response, explanation=explanation) from e
docker.errors.APIError: 400 Client Error for http://docker-socket-proxy:2375/v1.41/containers/524c514bf081d1ef02fb1aec345595c5d259e70cf40d2d0f7099aa2e2e91a262/start: Bad Request ("failed to create shim task: OCI runtime create failed: runc create failed: unable to start container process: exec: "/usr/bin/docker": stat /usr/bin/docker: no such file or directory: unknown")
[2023-09-27T16:32:40.651+0000] {taskinstance.py:1350} INFO - Marking task as FAILED. dag_id=web_scraping_dag, task_id=build_image, execution_date=20230927T163130, start_date=20230927T163239, end_date=20230927T163240
[2023-09-27T16:32:40.671+0000] {standard_task_runner.py:109} ERROR - Failed to execute job 275 for task build_image (400 Client Error for http://docker-socket-proxy:2375/v1.41/containers/524c514bf081d1ef02fb1aec345595c5d259e70cf40d2d0f7099aa2e2e91a262/start: Bad Request ("failed to create shim task: OCI runtime create failed: runc create failed: unable to start container process: exec: "/usr/bin/docker": stat /usr/bin/docker: no such file or directory: unknown"); 1847)
[2023-09-27T16:32:40.684+0000] {local_task_job_runner.py:225} INFO - Task exited with return code 1
[2023-09-27T16:32:40.711+0000] {taskinstance.py:2653} INFO - 0 downstream tasks scheduled from follow-on schedule check
