[2023-09-28T18:32:30.165+0000] {taskinstance.py:1103} INFO - Dependencies all met for dep_context=non-requeueable deps ti=<TaskInstance: web_scraping_dag.see_containers scheduled__2023-09-27T00:00:00+00:00 [queued]>
[2023-09-28T18:32:30.177+0000] {taskinstance.py:1103} INFO - Dependencies all met for dep_context=requeueable deps ti=<TaskInstance: web_scraping_dag.see_containers scheduled__2023-09-27T00:00:00+00:00 [queued]>
[2023-09-28T18:32:30.177+0000] {taskinstance.py:1308} INFO - Starting attempt 1 of 2
[2023-09-28T18:32:30.190+0000] {taskinstance.py:1327} INFO - Executing <Task(BashOperator): see_containers> on 2023-09-27 00:00:00+00:00
[2023-09-28T18:32:30.196+0000] {standard_task_runner.py:57} INFO - Started process 73 to run task
[2023-09-28T18:32:30.200+0000] {standard_task_runner.py:84} INFO - Running: ['***', 'tasks', 'run', 'web_scraping_dag', 'see_containers', 'scheduled__2023-09-27T00:00:00+00:00', '--job-id', '327', '--raw', '--subdir', 'DAGS_FOLDER/web_scrapping_test.py', '--cfg-path', '/tmp/tmppw0j64vo']
[2023-09-28T18:32:30.202+0000] {standard_task_runner.py:85} INFO - Job 327: Subtask see_containers
[2023-09-28T18:32:30.254+0000] {task_command.py:410} INFO - Running <TaskInstance: web_scraping_dag.see_containers scheduled__2023-09-27T00:00:00+00:00 [running]> on host 8106be9c0b63
[2023-09-28T18:32:30.335+0000] {taskinstance.py:1545} INFO - Exporting env vars: AIRFLOW_CTX_DAG_OWNER='***' AIRFLOW_CTX_DAG_ID='web_scraping_dag' AIRFLOW_CTX_TASK_ID='see_containers' AIRFLOW_CTX_EXECUTION_DATE='2023-09-27T00:00:00+00:00' AIRFLOW_CTX_TRY_NUMBER='1' AIRFLOW_CTX_DAG_RUN_ID='scheduled__2023-09-27T00:00:00+00:00'
[2023-09-28T18:32:30.336+0000] {subprocess.py:63} INFO - Tmp dir root location: /tmp
[2023-09-28T18:32:30.337+0000] {subprocess.py:75} INFO - Running command: ['/bin/bash', '-c', 'docker ps']
[2023-09-28T18:32:30.347+0000] {subprocess.py:86} INFO - Output:
[2023-09-28T18:32:30.535+0000] {subprocess.py:93} INFO - Got permission denied while trying to connect to the Docker daemon socket at unix:///var/run/docker.sock: Get "http://%2Fvar%2Frun%2Fdocker.sock/v1.24/containers/json": dial unix /var/run/docker.sock: connect: permission denied
[2023-09-28T18:32:30.536+0000] {subprocess.py:97} INFO - Command exited with return code 1
[2023-09-28T18:32:30.546+0000] {taskinstance.py:1824} ERROR - Task failed with exception
Traceback (most recent call last):
  File "/home/airflow/.local/lib/python3.10/site-packages/airflow/operators/bash.py", line 210, in execute
    raise AirflowException(
airflow.exceptions.AirflowException: Bash command failed. The command returned a non-zero exit code 1.
[2023-09-28T18:32:30.552+0000] {taskinstance.py:1345} INFO - Marking task as UP_FOR_RETRY. dag_id=web_scraping_dag, task_id=see_containers, execution_date=20230927T000000, start_date=20230928T183230, end_date=20230928T183230
[2023-09-28T18:32:30.567+0000] {standard_task_runner.py:104} ERROR - Failed to execute job 327 for task see_containers (Bash command failed. The command returned a non-zero exit code 1.; 73)
[2023-09-28T18:32:30.613+0000] {local_task_job_runner.py:225} INFO - Task exited with return code 1
[2023-09-28T18:32:30.636+0000] {taskinstance.py:2653} INFO - 0 downstream tasks scheduled from follow-on schedule check
