[2023-10-02T13:02:13.474+0000] {taskinstance.py:1103} INFO - Dependencies all met for dep_context=non-requeueable deps ti=<TaskInstance: web_scraping_dag.run_container scheduled__2023-10-01T00:00:00+00:00 [queued]>
[2023-10-02T13:02:13.494+0000] {taskinstance.py:1103} INFO - Dependencies all met for dep_context=requeueable deps ti=<TaskInstance: web_scraping_dag.run_container scheduled__2023-10-01T00:00:00+00:00 [queued]>
[2023-10-02T13:02:13.495+0000] {taskinstance.py:1308} INFO - Starting attempt 2 of 2
[2023-10-02T13:02:13.516+0000] {taskinstance.py:1327} INFO - Executing <Task(DockerOperator): run_container> on 2023-10-01 00:00:00+00:00
[2023-10-02T13:02:13.522+0000] {standard_task_runner.py:57} INFO - Started process 11328 to run task
[2023-10-02T13:02:13.527+0000] {standard_task_runner.py:84} INFO - Running: ['***', 'tasks', 'run', 'web_scraping_dag', 'run_container', 'scheduled__2023-10-01T00:00:00+00:00', '--job-id', '490', '--raw', '--subdir', 'DAGS_FOLDER/web_scrapping_test.py', '--cfg-path', '/tmp/tmpovvv1d6k']
[2023-10-02T13:02:13.529+0000] {standard_task_runner.py:85} INFO - Job 490: Subtask run_container
[2023-10-02T13:02:13.610+0000] {task_command.py:410} INFO - Running <TaskInstance: web_scraping_dag.run_container scheduled__2023-10-01T00:00:00+00:00 [running]> on host 6047a1c7123c
[2023-10-02T13:02:13.717+0000] {taskinstance.py:1545} INFO - Exporting env vars: AIRFLOW_CTX_DAG_OWNER='***' AIRFLOW_CTX_DAG_ID='web_scraping_dag' AIRFLOW_CTX_TASK_ID='run_container' AIRFLOW_CTX_EXECUTION_DATE='2023-10-01T00:00:00+00:00' AIRFLOW_CTX_TRY_NUMBER='2' AIRFLOW_CTX_DAG_RUN_ID='scheduled__2023-10-01T00:00:00+00:00'
[2023-10-02T13:02:13.747+0000] {docker.py:327} INFO - Pulling docker image my_selenium_image
[2023-10-02T13:02:25.640+0000] {taskinstance.py:1824} ERROR - Task failed with exception
Traceback (most recent call last):
  File "/home/airflow/.local/lib/python3.10/site-packages/docker/api/client.py", line 268, in _raise_for_status
    response.raise_for_status()
  File "/home/airflow/.local/lib/python3.10/site-packages/requests/models.py", line 1021, in raise_for_status
    raise HTTPError(http_error_msg, response=self)
requests.exceptions.HTTPError: 404 Client Error: Not Found for url: http://docker-socket-proxy:2375/v1.41/images/create?tag=latest&fromImage=my_selenium_image

The above exception was the direct cause of the following exception:

Traceback (most recent call last):
  File "/home/airflow/.local/lib/python3.10/site-packages/airflow/providers/docker/operators/docker.py", line 329, in execute
    for output in self.cli.pull(self.image, stream=True, decode=True):
  File "/home/airflow/.local/lib/python3.10/site-packages/docker/api/image.py", line 429, in pull
    self._raise_for_status(response)
  File "/home/airflow/.local/lib/python3.10/site-packages/docker/api/client.py", line 270, in _raise_for_status
    raise create_api_error_from_http_exception(e) from e
  File "/home/airflow/.local/lib/python3.10/site-packages/docker/errors.py", line 39, in create_api_error_from_http_exception
    raise cls(e, response=response, explanation=explanation) from e
docker.errors.ImageNotFound: 404 Client Error for http://docker-socket-proxy:2375/v1.41/images/create?tag=latest&fromImage=my_selenium_image: Not Found ("pull access denied for my_selenium_image, repository does not exist or may require 'docker login': denied: requested access to the resource is denied")
[2023-10-02T13:02:25.651+0000] {taskinstance.py:1345} INFO - Marking task as FAILED. dag_id=web_scraping_dag, task_id=run_container, execution_date=20231001T000000, start_date=20231002T130213, end_date=20231002T130225
[2023-10-02T13:02:25.664+0000] {standard_task_runner.py:104} ERROR - Failed to execute job 490 for task run_container (404 Client Error for http://docker-socket-proxy:2375/v1.41/images/create?tag=latest&fromImage=my_selenium_image: Not Found ("pull access denied for my_selenium_image, repository does not exist or may require 'docker login': denied: requested access to the resource is denied"); 11328)
[2023-10-02T13:02:25.673+0000] {local_task_job_runner.py:225} INFO - Task exited with return code 1
[2023-10-02T13:02:25.689+0000] {taskinstance.py:2653} INFO - 0 downstream tasks scheduled from follow-on schedule check
