[2023-09-21T13:57:54.001+0000] {taskinstance.py:1103} INFO - Dependencies all met for dep_context=non-requeueable deps ti=<TaskInstance: user_processing.store_user manual__2023-09-21T13:57:41.458634+00:00 [queued]>
[2023-09-21T13:57:54.011+0000] {taskinstance.py:1103} INFO - Dependencies all met for dep_context=requeueable deps ti=<TaskInstance: user_processing.store_user manual__2023-09-21T13:57:41.458634+00:00 [queued]>
[2023-09-21T13:57:54.012+0000] {taskinstance.py:1308} INFO - Starting attempt 1 of 1
[2023-09-21T13:57:54.029+0000] {taskinstance.py:1327} INFO - Executing <Task(PythonOperator): store_user> on 2023-09-21 13:57:41.458634+00:00
[2023-09-21T13:57:54.035+0000] {standard_task_runner.py:57} INFO - Started process 9479 to run task
[2023-09-21T13:57:54.039+0000] {standard_task_runner.py:84} INFO - Running: ['***', 'tasks', 'run', 'user_processing', 'store_user', 'manual__2023-09-21T13:57:41.458634+00:00', '--job-id', '48', '--raw', '--subdir', 'DAGS_FOLDER/user_processing.py', '--cfg-path', '/tmp/tmp0eoian13']
[2023-09-21T13:57:54.040+0000] {standard_task_runner.py:85} INFO - Job 48: Subtask store_user
[2023-09-21T13:57:54.097+0000] {task_command.py:410} INFO - Running <TaskInstance: user_processing.store_user manual__2023-09-21T13:57:41.458634+00:00 [running]> on host 90548f7cf83f
[2023-09-21T13:57:54.189+0000] {taskinstance.py:1547} INFO - Exporting env vars: AIRFLOW_CTX_DAG_OWNER='***' AIRFLOW_CTX_DAG_ID='user_processing' AIRFLOW_CTX_TASK_ID='store_user' AIRFLOW_CTX_EXECUTION_DATE='2023-09-21T13:57:41.458634+00:00' AIRFLOW_CTX_TRY_NUMBER='1' AIRFLOW_CTX_DAG_RUN_ID='manual__2023-09-21T13:57:41.458634+00:00'
[2023-09-21T13:57:54.193+0000] {postgres.py:159} INFO - Running copy expert: COPY users FROM stdin WITH DELIMITER as ',', filename: /tmp/processed_user.csv
[2023-09-21T13:57:54.205+0000] {base.py:73} INFO - Using connection ID '***' for task execution.
[2023-09-21T13:57:54.224+0000] {taskinstance.py:1824} ERROR - Task failed with exception
Traceback (most recent call last):
  File "/home/airflow/.local/lib/python3.7/site-packages/airflow/operators/python.py", line 181, in execute
    return_value = self.execute_callable()
  File "/home/airflow/.local/lib/python3.7/site-packages/airflow/operators/python.py", line 198, in execute_callable
    return self.python_callable(*self.op_args, **self.op_kwargs)
  File "/opt/airflow/dags/user_processing.py", line 29, in _store_user
    filename='/tmp/processed_user.csv'
  File "/home/airflow/.local/lib/python3.7/site-packages/airflow/providers/postgres/hooks/postgres.py", line 167, in copy_expert
    cur.copy_expert(sql, file)
psycopg2.errors.UndefinedTable: relation "users" does not exist

[2023-09-21T13:57:54.236+0000] {taskinstance.py:1350} INFO - Marking task as FAILED. dag_id=user_processing, task_id=store_user, execution_date=20230921T135741, start_date=20230921T135754, end_date=20230921T135754
[2023-09-21T13:57:54.255+0000] {standard_task_runner.py:109} ERROR - Failed to execute job 48 for task store_user (relation "users" does not exist
; 9479)
[2023-09-21T13:57:54.279+0000] {local_task_job_runner.py:225} INFO - Task exited with return code 1
[2023-09-21T13:57:54.300+0000] {taskinstance.py:2653} INFO - 0 downstream tasks scheduled from follow-on schedule check
