[2023-09-30T00:00:02.001+0000] {taskinstance.py:1103} INFO - Dependencies all met for dep_context=non-requeueable deps ti=<TaskInstance: web_scraping_dag.run_container scheduled__2023-09-29T00:00:00+00:00 [queued]>
[2023-09-30T00:00:02.016+0000] {taskinstance.py:1103} INFO - Dependencies all met for dep_context=requeueable deps ti=<TaskInstance: web_scraping_dag.run_container scheduled__2023-09-29T00:00:00+00:00 [queued]>
[2023-09-30T00:00:02.017+0000] {taskinstance.py:1308} INFO - Starting attempt 1 of 2
[2023-09-30T00:00:02.034+0000] {taskinstance.py:1327} INFO - Executing <Task(DockerOperator): run_container> on 2023-09-29 00:00:00+00:00
[2023-09-30T00:00:02.039+0000] {standard_task_runner.py:57} INFO - Started process 4827 to run task
[2023-09-30T00:00:02.044+0000] {standard_task_runner.py:84} INFO - Running: ['***', 'tasks', 'run', 'web_scraping_dag', 'run_container', 'scheduled__2023-09-29T00:00:00+00:00', '--job-id', '419', '--raw', '--subdir', 'DAGS_FOLDER/web_scrapping_test.py', '--cfg-path', '/tmp/tmpefc9ztbn']
[2023-09-30T00:00:02.046+0000] {standard_task_runner.py:85} INFO - Job 419: Subtask run_container
[2023-09-30T00:00:02.095+0000] {task_command.py:410} INFO - Running <TaskInstance: web_scraping_dag.run_container scheduled__2023-09-29T00:00:00+00:00 [running]> on host 6047a1c7123c
[2023-09-30T00:00:02.162+0000] {taskinstance.py:1545} INFO - Exporting env vars: AIRFLOW_CTX_DAG_OWNER='***' AIRFLOW_CTX_DAG_ID='web_scraping_dag' AIRFLOW_CTX_TASK_ID='run_container' AIRFLOW_CTX_EXECUTION_DATE='2023-09-29T00:00:00+00:00' AIRFLOW_CTX_TRY_NUMBER='1' AIRFLOW_CTX_DAG_RUN_ID='scheduled__2023-09-29T00:00:00+00:00'
[2023-09-30T00:00:02.184+0000] {docker.py:327} INFO - Pulling docker image my_selenium_image
[2023-09-30T00:00:03.214+0000] {taskinstance.py:1824} ERROR - Task failed with exception
Traceback (most recent call last):
  File "/home/airflow/.local/lib/python3.10/site-packages/docker/api/client.py", line 268, in _raise_for_status
    response.raise_for_status()
  File "/home/airflow/.local/lib/python3.10/site-packages/requests/models.py", line 1021, in raise_for_status
    raise HTTPError(http_error_msg, response=self)
requests.exceptions.HTTPError: 500 Server Error: Internal Server Error for url: http://docker-socket-proxy:2375/v1.41/images/create?tag=latest&fromImage=my_selenium_image

The above exception was the direct cause of the following exception:

Traceback (most recent call last):
  File "/home/airflow/.local/lib/python3.10/site-packages/airflow/providers/docker/operators/docker.py", line 329, in execute
    for output in self.cli.pull(self.image, stream=True, decode=True):
  File "/home/airflow/.local/lib/python3.10/site-packages/docker/api/image.py", line 429, in pull
    self._raise_for_status(response)
  File "/home/airflow/.local/lib/python3.10/site-packages/docker/api/client.py", line 270, in _raise_for_status
    raise create_api_error_from_http_exception(e) from e
  File "/home/airflow/.local/lib/python3.10/site-packages/docker/errors.py", line 39, in create_api_error_from_http_exception
    raise cls(e, response=response, explanation=explanation) from e
docker.errors.APIError: 500 Server Error for http://docker-socket-proxy:2375/v1.41/images/create?tag=latest&fromImage=my_selenium_image: Internal Server Error ("Head "https://registry-1.docker.io/v2/library/my_selenium_image/manifests/latest": error parsing HTTP 429 response body: invalid character 'S' looking for beginning of value: "Server capacity exceeded.\n"")
[2023-09-30T00:00:03.233+0000] {taskinstance.py:1345} INFO - Marking task as UP_FOR_RETRY. dag_id=web_scraping_dag, task_id=run_container, execution_date=20230929T000000, start_date=20230930T000002, end_date=20230930T000003
[2023-09-30T00:00:03.254+0000] {standard_task_runner.py:104} ERROR - Failed to execute job 419 for task run_container (500 Server Error for http://docker-socket-proxy:2375/v1.41/images/create?tag=latest&fromImage=my_selenium_image: Internal Server Error ("Head "https://registry-1.docker.io/v2/library/my_selenium_image/manifests/latest": error parsing HTTP 429 response body: invalid character 'S' looking for beginning of value: "Server capacity exceeded.\n""); 4827)
[2023-09-30T00:00:03.300+0000] {local_task_job_runner.py:225} INFO - Task exited with return code 1
[2023-09-30T00:00:03.372+0000] {taskinstance.py:2653} INFO - 0 downstream tasks scheduled from follow-on schedule check
