[2023-09-26T17:55:18.312+0000] {taskinstance.py:1103} INFO - Dependencies all met for dep_context=non-requeueable deps ti=<TaskInstance: user_processing.set_search_path scheduled__2023-09-25T00:00:00+00:00 [queued]>
[2023-09-26T17:55:18.339+0000] {taskinstance.py:1103} INFO - Dependencies all met for dep_context=requeueable deps ti=<TaskInstance: user_processing.set_search_path scheduled__2023-09-25T00:00:00+00:00 [queued]>
[2023-09-26T17:55:18.339+0000] {taskinstance.py:1308} INFO - Starting attempt 1 of 1
[2023-09-26T17:55:18.368+0000] {taskinstance.py:1327} INFO - Executing <Task(PostgresOperator): set_search_path> on 2023-09-25 00:00:00+00:00
[2023-09-26T17:55:18.376+0000] {standard_task_runner.py:57} INFO - Started process 69 to run task
[2023-09-26T17:55:18.381+0000] {standard_task_runner.py:84} INFO - Running: ['***', 'tasks', 'run', 'user_processing', 'set_search_path', 'scheduled__2023-09-25T00:00:00+00:00', '--job-id', '136', '--raw', '--subdir', 'DAGS_FOLDER/user_processing.py', '--cfg-path', '/tmp/tmpt_1_2f5a']
[2023-09-26T17:55:18.385+0000] {standard_task_runner.py:85} INFO - Job 136: Subtask set_search_path
[2023-09-26T17:55:18.465+0000] {task_command.py:410} INFO - Running <TaskInstance: user_processing.set_search_path scheduled__2023-09-25T00:00:00+00:00 [running]> on host 73e7c51b7e3f
[2023-09-26T17:55:18.865+0000] {taskinstance.py:1547} INFO - Exporting env vars: AIRFLOW_CTX_DAG_OWNER='***' AIRFLOW_CTX_DAG_ID='user_processing' AIRFLOW_CTX_TASK_ID='set_search_path' AIRFLOW_CTX_EXECUTION_DATE='2023-09-25T00:00:00+00:00' AIRFLOW_CTX_TRY_NUMBER='1' AIRFLOW_CTX_DAG_RUN_ID='scheduled__2023-09-25T00:00:00+00:00'
[2023-09-26T17:55:18.867+0000] {sql.py:265} INFO - Executing: SET search_path TO ***_ini
[2023-09-26T17:55:18.879+0000] {base.py:73} INFO - Using connection ID '***' for task execution.
[2023-09-26T17:55:19.038+0000] {base.py:73} INFO - Using connection ID '***' for task execution.
[2023-09-26T17:55:22.121+0000] {taskinstance.py:1824} ERROR - Task failed with exception
Traceback (most recent call last):
  File "/home/airflow/.local/lib/python3.7/site-packages/airflow/providers/common/sql/operators/sql.py", line 277, in execute
    **extra_kwargs,
  File "/home/airflow/.local/lib/python3.7/site-packages/airflow/providers/common/sql/hooks/sql.py", line 342, in run
    with closing(self.get_conn()) as conn:
  File "/home/airflow/.local/lib/python3.7/site-packages/airflow/providers/postgres/hooks/postgres.py", line 145, in get_conn
    self.conn = psycopg2.connect(**conn_args)
  File "/home/airflow/.local/lib/python3.7/site-packages/psycopg2/__init__.py", line 122, in connect
    conn = _connect(dsn, connection_factory=connection_factory, **kwasync)
psycopg2.OperationalError: connection to server at "172.27.70.244", port 5434 failed: No route to host
	Is the server running on that host and accepting TCP/IP connections?

[2023-09-26T17:55:22.133+0000] {taskinstance.py:1350} INFO - Marking task as FAILED. dag_id=user_processing, task_id=set_search_path, execution_date=20230925T000000, start_date=20230926T175518, end_date=20230926T175522
[2023-09-26T17:55:22.160+0000] {standard_task_runner.py:109} ERROR - Failed to execute job 136 for task set_search_path (connection to server at "172.27.70.244", port 5434 failed: No route to host
	Is the server running on that host and accepting TCP/IP connections?
; 69)
[2023-09-26T17:55:22.177+0000] {local_task_job_runner.py:225} INFO - Task exited with return code 1
[2023-09-26T17:55:22.222+0000] {taskinstance.py:2653} INFO - 0 downstream tasks scheduled from follow-on schedule check
