[2023-09-27T14:01:36.623+0000] {taskinstance.py:1103} INFO - Dependencies all met for dep_context=non-requeueable deps ti=<TaskInstance: web_scraping_dag.build_image manual__2023-09-27T14:00:33.452214+00:00 [queued]>
[2023-09-27T14:01:36.640+0000] {taskinstance.py:1103} INFO - Dependencies all met for dep_context=requeueable deps ti=<TaskInstance: web_scraping_dag.build_image manual__2023-09-27T14:00:33.452214+00:00 [queued]>
[2023-09-27T14:01:36.640+0000] {taskinstance.py:1308} INFO - Starting attempt 2 of 2
[2023-09-27T14:01:36.662+0000] {taskinstance.py:1327} INFO - Executing <Task(DockerOperator): build_image> on 2023-09-27 14:00:33.452214+00:00
[2023-09-27T14:01:36.668+0000] {standard_task_runner.py:57} INFO - Started process 223 to run task
[2023-09-27T14:01:36.671+0000] {standard_task_runner.py:84} INFO - Running: ['***', 'tasks', 'run', 'web_scraping_dag', 'build_image', 'manual__2023-09-27T14:00:33.452214+00:00', '--job-id', '263', '--raw', '--subdir', 'DAGS_FOLDER/web_scrapping_test.py', '--cfg-path', '/tmp/tmp_s00duhv']
[2023-09-27T14:01:36.673+0000] {standard_task_runner.py:85} INFO - Job 263: Subtask build_image
[2023-09-27T14:01:36.732+0000] {task_command.py:410} INFO - Running <TaskInstance: web_scraping_dag.build_image manual__2023-09-27T14:00:33.452214+00:00 [running]> on host 0908c3cef604
[2023-09-27T14:01:36.843+0000] {taskinstance.py:1547} INFO - Exporting env vars: AIRFLOW_CTX_DAG_OWNER='***' AIRFLOW_CTX_DAG_ID='web_scraping_dag' AIRFLOW_CTX_TASK_ID='build_image' AIRFLOW_CTX_EXECUTION_DATE='2023-09-27T14:00:33.452214+00:00' AIRFLOW_CTX_TRY_NUMBER='2' AIRFLOW_CTX_DAG_RUN_ID='manual__2023-09-27T14:00:33.452214+00:00'
[2023-09-27T14:01:36.937+0000] {docker.py:246} INFO - Starting docker container from image my_selenium_image
[2023-09-27T14:01:37.685+0000] {taskinstance.py:1824} ERROR - Task failed with exception
Traceback (most recent call last):
  File "/home/airflow/.local/lib/python3.7/site-packages/docker/api/client.py", line 268, in _raise_for_status
    response.raise_for_status()
  File "/home/airflow/.local/lib/python3.7/site-packages/requests/models.py", line 1021, in raise_for_status
    raise HTTPError(http_error_msg, response=self)
requests.exceptions.HTTPError: 400 Client Error: Bad Request for url: http://docker-socket-proxy:2375/v1.41/containers/fa6781b06403b601c1aba1b6cea2562135eb723d1dac0ca46c81f72a3075e6b7/start

The above exception was the direct cause of the following exception:

Traceback (most recent call last):
  File "/home/airflow/.local/lib/python3.7/site-packages/airflow/providers/docker/operators/docker.py", line 343, in execute
    return self._run_image()
  File "/home/airflow/.local/lib/python3.7/site-packages/airflow/providers/docker/operators/docker.py", line 265, in _run_image
    return self._run_image_with_mounts(self.mounts, add_tmp_variable=False)
  File "/home/airflow/.local/lib/python3.7/site-packages/airflow/providers/docker/operators/docker.py", line 297, in _run_image_with_mounts
    self.cli.start(self.container['Id'])
  File "/home/airflow/.local/lib/python3.7/site-packages/docker/utils/decorators.py", line 19, in wrapped
    return f(self, resource_id, *args, **kwargs)
  File "/home/airflow/.local/lib/python3.7/site-packages/docker/api/container.py", line 1127, in start
    self._raise_for_status(res)
  File "/home/airflow/.local/lib/python3.7/site-packages/docker/api/client.py", line 270, in _raise_for_status
    raise create_api_error_from_http_exception(e) from e
  File "/home/airflow/.local/lib/python3.7/site-packages/docker/errors.py", line 39, in create_api_error_from_http_exception
    raise cls(e, response=response, explanation=explanation) from e
docker.errors.APIError: 400 Client Error for http://docker-socket-proxy:2375/v1.41/containers/fa6781b06403b601c1aba1b6cea2562135eb723d1dac0ca46c81f72a3075e6b7/start: Bad Request ("failed to create shim task: OCI runtime create failed: runc create failed: unable to start container process: exec: "docker": executable file not found in $PATH: unknown")
[2023-09-27T14:01:37.694+0000] {taskinstance.py:1350} INFO - Marking task as FAILED. dag_id=web_scraping_dag, task_id=build_image, execution_date=20230927T140033, start_date=20230927T140136, end_date=20230927T140137
[2023-09-27T14:01:37.709+0000] {standard_task_runner.py:109} ERROR - Failed to execute job 263 for task build_image (400 Client Error for http://docker-socket-proxy:2375/v1.41/containers/fa6781b06403b601c1aba1b6cea2562135eb723d1dac0ca46c81f72a3075e6b7/start: Bad Request ("failed to create shim task: OCI runtime create failed: runc create failed: unable to start container process: exec: "docker": executable file not found in $PATH: unknown"); 223)
[2023-09-27T14:01:37.730+0000] {local_task_job_runner.py:225} INFO - Task exited with return code 1
[2023-09-27T14:01:37.760+0000] {taskinstance.py:2653} INFO - 0 downstream tasks scheduled from follow-on schedule check
