[2023-09-26T22:29:21.153+0000] {taskinstance.py:1103} INFO - Dependencies all met for dep_context=non-requeueable deps ti=<TaskInstance: web_scraping_dag.build_image manual__2023-09-26T22:29:19.615371+00:00 [queued]>
[2023-09-26T22:29:21.166+0000] {taskinstance.py:1103} INFO - Dependencies all met for dep_context=requeueable deps ti=<TaskInstance: web_scraping_dag.build_image manual__2023-09-26T22:29:19.615371+00:00 [queued]>
[2023-09-26T22:29:21.166+0000] {taskinstance.py:1308} INFO - Starting attempt 1 of 2
[2023-09-26T22:29:21.186+0000] {taskinstance.py:1327} INFO - Executing <Task(DockerOperator): build_image> on 2023-09-26 22:29:19.615371+00:00
[2023-09-26T22:29:21.192+0000] {standard_task_runner.py:57} INFO - Started process 216 to run task
[2023-09-26T22:29:21.196+0000] {standard_task_runner.py:84} INFO - Running: ['***', 'tasks', 'run', 'web_scraping_dag', 'build_image', 'manual__2023-09-26T22:29:19.615371+00:00', '--job-id', '189', '--raw', '--subdir', 'DAGS_FOLDER/web_scrapping_test.py', '--cfg-path', '/tmp/tmpgdi5t9e6']
[2023-09-26T22:29:21.197+0000] {standard_task_runner.py:85} INFO - Job 189: Subtask build_image
[2023-09-26T22:29:21.256+0000] {task_command.py:410} INFO - Running <TaskInstance: web_scraping_dag.build_image manual__2023-09-26T22:29:19.615371+00:00 [running]> on host ad914e625908
[2023-09-26T22:29:21.355+0000] {taskinstance.py:1547} INFO - Exporting env vars: AIRFLOW_CTX_DAG_OWNER='***' AIRFLOW_CTX_DAG_ID='web_scraping_dag' AIRFLOW_CTX_TASK_ID='build_image' AIRFLOW_CTX_EXECUTION_DATE='2023-09-26T22:29:19.615371+00:00' AIRFLOW_CTX_TRY_NUMBER='1' AIRFLOW_CTX_DAG_RUN_ID='manual__2023-09-26T22:29:19.615371+00:00'
[2023-09-26T22:29:21.430+0000] {docker.py:334} INFO - Starting docker container from image my_selenium_image
[2023-09-26T22:29:22.164+0000] {taskinstance.py:1824} ERROR - Task failed with exception
Traceback (most recent call last):
  File "/home/airflow/.local/lib/python3.7/site-packages/docker/api/client.py", line 268, in _raise_for_status
    response.raise_for_status()
  File "/home/airflow/.local/lib/python3.7/site-packages/requests/models.py", line 1021, in raise_for_status
    raise HTTPError(http_error_msg, response=self)
requests.exceptions.HTTPError: 400 Client Error: Bad Request for url: http+docker://localhost/v1.41/containers/3d0d844e13fccfe00178eac97d50f2611d318e7c16461419c900cd3a4cd206dd/start

The above exception was the direct cause of the following exception:

Traceback (most recent call last):
  File "/home/airflow/.local/lib/python3.7/site-packages/airflow/providers/docker/operators/docker.py", line 478, in execute
    return self._run_image()
  File "/home/airflow/.local/lib/python3.7/site-packages/airflow/providers/docker/operators/docker.py", line 351, in _run_image
    return self._run_image_with_mounts(self.mounts, add_tmp_variable=False)
  File "/home/airflow/.local/lib/python3.7/site-packages/airflow/providers/docker/operators/docker.py", line 397, in _run_image_with_mounts
    self.cli.start(self.container["Id"])
  File "/home/airflow/.local/lib/python3.7/site-packages/docker/utils/decorators.py", line 19, in wrapped
    return f(self, resource_id, *args, **kwargs)
  File "/home/airflow/.local/lib/python3.7/site-packages/docker/api/container.py", line 1127, in start
    self._raise_for_status(res)
  File "/home/airflow/.local/lib/python3.7/site-packages/docker/api/client.py", line 270, in _raise_for_status
    raise create_api_error_from_http_exception(e) from e
  File "/home/airflow/.local/lib/python3.7/site-packages/docker/errors.py", line 39, in create_api_error_from_http_exception
    raise cls(e, response=response, explanation=explanation) from e
docker.errors.APIError: 400 Client Error for http+docker://localhost/v1.41/containers/3d0d844e13fccfe00178eac97d50f2611d318e7c16461419c900cd3a4cd206dd/start: Bad Request ("failed to create shim task: OCI runtime create failed: runc create failed: unable to start container process: exec: "docker": executable file not found in $PATH: unknown")
[2023-09-26T22:29:22.173+0000] {taskinstance.py:1350} INFO - Marking task as UP_FOR_RETRY. dag_id=web_scraping_dag, task_id=build_image, execution_date=20230926T222919, start_date=20230926T222921, end_date=20230926T222922
[2023-09-26T22:29:22.188+0000] {standard_task_runner.py:109} ERROR - Failed to execute job 189 for task build_image (400 Client Error for http+docker://localhost/v1.41/containers/3d0d844e13fccfe00178eac97d50f2611d318e7c16461419c900cd3a4cd206dd/start: Bad Request ("failed to create shim task: OCI runtime create failed: runc create failed: unable to start container process: exec: "docker": executable file not found in $PATH: unknown"); 216)
[2023-09-26T22:29:22.212+0000] {local_task_job_runner.py:225} INFO - Task exited with return code 1
[2023-09-26T22:29:22.242+0000] {taskinstance.py:2653} INFO - 0 downstream tasks scheduled from follow-on schedule check
