[2023-09-27T17:56:55.667+0000] {taskinstance.py:1103} INFO - Dependencies all met for dep_context=non-requeueable deps ti=<TaskInstance: web_scraping_dag.see_containers manual__2023-09-27T17:55:28.751636+00:00 [queued]>
[2023-09-27T17:56:55.895+0000] {taskinstance.py:1103} INFO - Dependencies all met for dep_context=requeueable deps ti=<TaskInstance: web_scraping_dag.see_containers manual__2023-09-27T17:55:28.751636+00:00 [queued]>
[2023-09-27T17:56:55.897+0000] {taskinstance.py:1308} INFO - Starting attempt 2 of 2
[2023-09-27T17:56:56.052+0000] {taskinstance.py:1327} INFO - Executing <Task(BashOperator): see_containers> on 2023-09-27 17:55:28.751636+00:00
[2023-09-27T17:56:56.097+0000] {standard_task_runner.py:57} INFO - Started process 133 to run task
[2023-09-27T17:56:56.118+0000] {standard_task_runner.py:84} INFO - Running: ['***', 'tasks', 'run', 'web_scraping_dag', 'see_containers', 'manual__2023-09-27T17:55:28.751636+00:00', '--job-id', '309', '--raw', '--subdir', 'DAGS_FOLDER/web_scrapping_test.py', '--cfg-path', '/tmp/tmpqb3qdcyo']
[2023-09-27T17:56:56.137+0000] {standard_task_runner.py:85} INFO - Job 309: Subtask see_containers
[2023-09-27T17:56:56.534+0000] {task_command.py:410} INFO - Running <TaskInstance: web_scraping_dag.see_containers manual__2023-09-27T17:55:28.751636+00:00 [running]> on host 08c79dd1a303
[2023-09-27T17:56:56.968+0000] {taskinstance.py:1545} INFO - Exporting env vars: AIRFLOW_CTX_DAG_OWNER='***' AIRFLOW_CTX_DAG_ID='web_scraping_dag' AIRFLOW_CTX_TASK_ID='see_containers' AIRFLOW_CTX_EXECUTION_DATE='2023-09-27T17:55:28.751636+00:00' AIRFLOW_CTX_TRY_NUMBER='2' AIRFLOW_CTX_DAG_RUN_ID='manual__2023-09-27T17:55:28.751636+00:00'
[2023-09-27T17:56:56.972+0000] {subprocess.py:63} INFO - Tmp dir root location: /tmp
[2023-09-27T17:56:56.973+0000] {subprocess.py:75} INFO - Running command: ['/bin/bash', '-c', 'docker ps']
[2023-09-27T17:56:57.014+0000] {subprocess.py:86} INFO - Output:
[2023-09-27T17:56:57.227+0000] {subprocess.py:93} INFO - Got permission denied while trying to connect to the Docker daemon socket at unix:///var/run/docker.sock: Get "http://%2Fvar%2Frun%2Fdocker.sock/v1.24/containers/json": dial unix /var/run/docker.sock: connect: permission denied
[2023-09-27T17:56:57.236+0000] {subprocess.py:97} INFO - Command exited with return code 1
[2023-09-27T17:56:57.275+0000] {taskinstance.py:1824} ERROR - Task failed with exception
Traceback (most recent call last):
  File "/home/airflow/.local/lib/python3.10/site-packages/airflow/operators/bash.py", line 210, in execute
    raise AirflowException(
airflow.exceptions.AirflowException: Bash command failed. The command returned a non-zero exit code 1.
[2023-09-27T17:56:57.288+0000] {taskinstance.py:1345} INFO - Marking task as FAILED. dag_id=web_scraping_dag, task_id=see_containers, execution_date=20230927T175528, start_date=20230927T175655, end_date=20230927T175657
[2023-09-27T17:56:57.372+0000] {standard_task_runner.py:104} ERROR - Failed to execute job 309 for task see_containers (Bash command failed. The command returned a non-zero exit code 1.; 133)
[2023-09-27T17:56:57.456+0000] {local_task_job_runner.py:225} INFO - Task exited with return code 1
[2023-09-27T17:56:57.551+0000] {taskinstance.py:2653} INFO - 0 downstream tasks scheduled from follow-on schedule check
