[2023-09-21T12:53:51.602+0000] {taskinstance.py:1103} INFO - Dependencies all met for dep_context=non-requeueable deps ti=<TaskInstance: user_processing.is_api_available manual__2023-09-21T12:53:24.761909+00:00 [queued]>
[2023-09-21T12:53:51.628+0000] {taskinstance.py:1103} INFO - Dependencies all met for dep_context=requeueable deps ti=<TaskInstance: user_processing.is_api_available manual__2023-09-21T12:53:24.761909+00:00 [queued]>
[2023-09-21T12:53:51.629+0000] {taskinstance.py:1308} INFO - Starting attempt 1 of 1
[2023-09-21T12:53:51.665+0000] {taskinstance.py:1327} INFO - Executing <Task(HttpSensor): is_api_available> on 2023-09-21 12:53:24.761909+00:00
[2023-09-21T12:53:51.680+0000] {standard_task_runner.py:57} INFO - Started process 8359 to run task
[2023-09-21T12:53:51.689+0000] {standard_task_runner.py:84} INFO - Running: ['***', 'tasks', 'run', 'user_processing', 'is_api_available', 'manual__2023-09-21T12:53:24.761909+00:00', '--job-id', '38', '--raw', '--subdir', 'DAGS_FOLDER/user_processing.py', '--cfg-path', '/tmp/tmpc9srgszs']
[2023-09-21T12:53:51.690+0000] {standard_task_runner.py:85} INFO - Job 38: Subtask is_api_available
[2023-09-21T12:53:51.803+0000] {task_command.py:410} INFO - Running <TaskInstance: user_processing.is_api_available manual__2023-09-21T12:53:24.761909+00:00 [running]> on host 90548f7cf83f
[2023-09-21T12:53:51.982+0000] {taskinstance.py:1547} INFO - Exporting env vars: AIRFLOW_CTX_DAG_OWNER='***' AIRFLOW_CTX_DAG_ID='user_processing' AIRFLOW_CTX_TASK_ID='is_api_available' AIRFLOW_CTX_EXECUTION_DATE='2023-09-21T12:53:24.761909+00:00' AIRFLOW_CTX_TRY_NUMBER='1' AIRFLOW_CTX_DAG_RUN_ID='manual__2023-09-21T12:53:24.761909+00:00'
[2023-09-21T12:53:51.987+0000] {http.py:122} INFO - Poking: api/
[2023-09-21T12:53:52.022+0000] {taskinstance.py:1824} ERROR - Task failed with exception
Traceback (most recent call last):
  File "/home/airflow/.local/lib/python3.7/site-packages/airflow/sensors/base.py", line 225, in execute
    raise e
  File "/home/airflow/.local/lib/python3.7/site-packages/airflow/sensors/base.py", line 212, in execute
    poke_return = self.poke(context)
  File "/home/airflow/.local/lib/python3.7/site-packages/airflow/providers/http/sensors/http.py", line 137, in poke
    raise exc
  File "/home/airflow/.local/lib/python3.7/site-packages/airflow/providers/http/sensors/http.py", line 128, in poke
    extra_options=self.extra_options,
  File "/home/airflow/.local/lib/python3.7/site-packages/airflow/providers/http/hooks/http.py", line 148, in run
    session = self.get_conn(headers)
  File "/home/airflow/.local/lib/python3.7/site-packages/airflow/providers/http/hooks/http.py", line 100, in get_conn
    conn = self.get_connection(self.http_conn_id)
  File "/home/airflow/.local/lib/python3.7/site-packages/airflow/hooks/base.py", line 72, in get_connection
    conn = Connection.get_connection_from_secrets(conn_id)
  File "/home/airflow/.local/lib/python3.7/site-packages/airflow/models/connection.py", line 463, in get_connection_from_secrets
    raise AirflowNotFoundException(f"The conn_id `{conn_id}` isn't defined")
airflow.exceptions.AirflowNotFoundException: The conn_id `user_api` isn't defined
[2023-09-21T12:53:52.029+0000] {taskinstance.py:1350} INFO - Marking task as FAILED. dag_id=user_processing, task_id=is_api_available, execution_date=20230921T125324, start_date=20230921T125351, end_date=20230921T125352
[2023-09-21T12:53:52.062+0000] {standard_task_runner.py:109} ERROR - Failed to execute job 38 for task is_api_available (The conn_id `user_api` isn't defined; 8359)
[2023-09-21T12:53:52.086+0000] {local_task_job_runner.py:225} INFO - Task exited with return code 1
[2023-09-21T12:53:52.160+0000] {taskinstance.py:2653} INFO - 0 downstream tasks scheduled from follow-on schedule check
